Workbook
Name Slicer_Recruiter: #N/A

Sheet About
B1: Request Handoff Check
B2: Where hiring requests get stuck between approval and iCIMS
B3: A mini project by Showrish Reddy Sampath · Fall 2026 · All data is synthetic
B5: The question
B6: Hiring requests get approved on a request site, then retyped by hand into iCIMS for posting.
B7: So where does time get lost, and where does the data stop matching between the two systems?
B9: What I found
B10: • Finance is the bottleneck: 7.4 days per approval, nearly 3x the other steps, with 3 approvals stuck 2+ weeks.
B11: • Approved requests wait about 6 days before they're opened in iCIMS, lost to manual re-entry.
B12: • Average time to fill is 56.1 days, from final approval to accepted offer.
B13: • 7 fields don't match between systems: 4 job titles, 2 hiring managers and 1 department.
B14: • 3 iCIMS jobs have no request on file, including one with a typo in its ID (O instead of 0).
... B35: • Blue headers are fields from the system exports. Green headers are checks I added.

Sheet Dashboard
A1: Request Handoff Check | F1: KPI | G1: Value
A2: As of date | B2: 46295 | F2: Total requests | G2: =COUNTA(ReqSite_Export!A2:A82) -> 81
F3: Approved | G3: =COUNTIF(ReqSite_Export!J2:J82,"Approved") -> 60
A4: Title mismatches | B4: =COUNTIF(iCIMS_Export!Q2:Q57,FALSE) -> 4 | F4: Stale gaps | G4: =COUNTIF(ReqSite_Export!O2:O82,"Stale gap") -> 5
A5: Manager mismatches | B5: =COUNTIF(iCIMS_Export!S2:S57,FALSE) -> 2 | F5: Recent gaps | G5: =COUNTIF(ReqSite_Export!O2:O82,"Recent") -> 3
A6: Dept mismatches | B6: =COUNTIF(iCIMS_Export!U2:U57,FALSE) -> 1 | F6: No request on file | G6: =COUNTIF(iCIMS_Export!O2:O57,"No request on file") -> 3
A7: Duplicate rows | B7: =COUNTIF(ReqSite_Export!P2:P82,">1") -> 2 | F7: Opened before approval | G7: =COUNTIF(iCIMS_Export!O2:O57,"Opened before approval") -> 1
A8: Dates stored as text | B8: =COUNTIF(iCIMS_Export!H2:H57,"*") -> 3 | F8: Field mismatches | G8: =SUM(B4:B6) -> 7
A9: Missing locations | B9: =COUNTBLANK(ReqSite_Export!H2:H82) -> 3 | F9: Duplicate pairs | G9: =B7/2 -> 1
F10: Avg approval cycle | G10: =AVERAGE(ReqSite_Export!Q2:Q82) -> 12.75
A11: Approval step | B11: Avg days | C11: Pending | D11: Pending 14+ days | F11: Slowest step | G11: =_xlfn.XLOOKUP(MAX(B12:B14),B12:B14,A12:A14) -> 2 - Finance
A12: {=_xlfn.UNIQUE(Approvals_Log!B2:B217)} -> 1 - Dept Head | B12: =AVERAGEIFS(Approvals_Log!$G$2:$G$217,Approvals_Log!$B$2:$B$217,A12,Approvals_Log!$F$2:$F$217,"<>Pending") -> 2.6282051 | C12: =COUNTIFS(Approvals_Log!$F$2:$F$217,"Pending",Approvals_Log!$B$2:$B$217,A12) -> 3 | D12: =COUNTIFS(Approvals_Log!$F$2:$F$217,"Pending",Approvals_Log!$B$2:$B$217,A12,Approvals_Log!$G$2:$G$217,">=14") -> 1 | F12: Avg hand-off days | G12: =B16 -> 6.0192308
A13: 2 - Finance | B13: =AVERAGEIFS(Approvals_Log!$G$2:$G$217,Approvals_Log!$B$2:$B$217,A13,Approvals_Log!$F$2:$F$217,"<>Pending") -> 7.4242424 | C13: =COUNTIFS(Approvals_Log!$F$2:$F$217,"Pending",Approvals_Log!$B$2:$B$217,A13) -> 7 | D13: =COUNTIFS(Approvals_Log!$F$2:$F$217,"Pending",Approvals_Log!$B$2:$B$217,A13,Approvals_Log!$G$2:$G$217,">=14") -> 3 | F13: Avg time to fill | G13: =B17 -> 56.131579
A14: 3 - HR Business Partner | B14: =AVERAGEIFS(Approvals_Log!$G$2:$G$217,Approvals_Log!$B$2:$B$217,A14,Approvals_Log!$F$2:$F$217,"<>Pending") -> 2.6333333 | C14: =COUNTIFS(Approvals_Log!$F$2:$F$217,"Pending",Approvals_Log!$B$2:$B$217,A14) -> 2 | D14: =COUNTIFS(Approvals_Log!$F$2:$F$217,"Pending",Approvals_Log!$B$2:$B$217,A14,Approvals_Log!$G$2:$G$217,">=14") -> 0
A16: Avg hand-off days | B16: =AVERAGE(iCIMS_Export!W2:W57) -> 6.0192308
A17: Avg time to fill | B17: =AVERAGE(iCIMS_Export!X2:X57) -> 56.131579

Sheet ReqSite_Export
A1: Request ID | B1: Submitted On | C1: Hiring Manager | D1: Department | E1: Job Title | F1: Request Type | G1: Employment Type | H1: Location | I1: Target Start | J1: Request Status | K1: Final Approval Date | L1: In_iCIMS | M1: iCIMS_Job_ID | N1: Days_Since_Approval | O1: Gap_Flag | P1: Dup_Check | Q1: Approval_Cycle
A2: RR-26-0001 | B2: 46027 | C2: Kevin Doyle | D2: IT | E2: Systems Administrator | F2: New Headcount | G2: Full-time | H2: London | I2: 46111 | J2: Approved | K2: 46048 | L2: =IF(COUNTIF(iCIMS_Export!M:M,A2)>0,"Yes","No") -> Yes | M2: =_xlfn.XLOOKUP(A2,iCIMS_Export!$M$2:$M$57,iCIMS_Export!$A$2:$A$57,"") -> 4103 | N2: =IF(J2="Approved",Dashboard!$B$2-K2,"") -> 247 | O2: =IF(AND(J2="Approved",L2="No"),IF(N2>7,"Stale gap","Recent"),"") | P2: =COUNTIFS($C$2:$C$82,C2,$E$2:$E$82,E2,$B$2:$B$82,">="&B2-7,$B$2:$B$82,"<="&B2+7) -> 1 | Q2: =IF(J2="Approved",K2-B2,"") -> 21
A3: RR-26-0002 | B3: 46030 | C3: Elena Vasquez | D3: Research | E3: Research Director | F3: New Headcount | G3: Full-time | H3: Remote (US) | I3: 46111 | J3: Approved | K3: 46043 | L3: =IF(COUNTIF(iCIMS_Export!M:M,A3)>0,"Yes","No") -> Yes | M3: =_xlfn.XLOOKUP(A3,iCIMS_Export!$M$2:$M$57,iCIMS_Export!$A$2:$A$57,"") -> 4101 | N3: =IF(J3="Approved",Dashboard!$B$2-K3,"") -> 252 | O3: =IF(AND(J3="Approved",L3="No"),IF(N3>7,"Stale gap","Recent"),"") | P3: =COUNTIFS($C$2:$C$82,C3,$E$2:$E$82,E3,$B$2:$B$82,">="&B3-7,$B$2:$B$82,"<="&B3+7) -> 1 | Q3: =IF(J3="Approved",K3-B3,"") -> 13
A4: RR-26-0003 | B4: 46035 | C4: Carlos Mendes | D4: Sales | E4: Sales Operations Analyst | F4: Backfill | G4: Part-time | H4: London | I4: 46083 | J4: Approved | K4: 46045 | L4: =IF(COUNTIF(iCIMS_Export!M:M,A4)>0,"Yes","No") -> Yes | M4: =_xlfn.XLOOKUP(A4,iCIMS_Export!$M$2:$M$57,iCIMS_Export!$A$2:$A$57,"") -> 4102 | N4: =IF(J4="Approved",Dashboard!$B$2-K4,"") -> 250 | O4: =IF(AND(J4="Approved",L4="No"),IF(N4>7,"Stale gap","Recent"),"") | P4: =COUNTIFS($C$2:$C$82,C4,$E$2:$E$82,E4,$B$2:$B$82,">="&B4-7,$B$2:$B$82,"<="&B4+7) -> 1 | Q4: =IF(J4="Approved",K4-B4,"") -> 10
A5: RR-26-0004 | B5: 46037 | C5: Michael Grant | D5: Sales | E5: Account Executive | F5: Backfill | G5: Full-time | H5: Boston | I5: 46120 | J5: Approved | K5: 46048 | L5: =IF(COUNTIF(iCIMS_Export!M:M,A5)>0,"Yes","No") -> Yes | M5: =_xlfn.XLOOKUP(A5,iCIMS_Export!$M$2:$M$57,iCIMS_Export!$A$2:$A$57,"") -> 4106 | N5: =IF(J5="Approved",Dashboard!$B$2-K5,"") -> 247 | O5: =IF(AND(J5="Approved",L5="No"),IF(N5>7,"Stale gap","Recent"),"") | P5: =COUNTIFS($C$2:$C$82,C5,$E$2:$E$82,E5,$B$2:$B$82,">="&B5-7,$B$2:$B$82,"<="&B5+7) -> 1 | Q5: =IF(J5="Approved",K5-B5,"") -> 11
A6: RR-26-0005 | B6: 46038 | C6: Victor Salgado | D6: Events | E6: Event Coordinator | F6: Backfill | G6: Full-time | H6: London | I6: 46090 | J6: Approved | K6: 46048 | L6: =IF(COUNTIF(iCIMS_Export!M:M,A6)>0,"Yes","No") -> Yes | M6: =_xlfn.XLOOKUP(A6,iCIMS_Export!$M$2:$M$57,iCIMS_Export!$A$2:$A$57,"") -> 4107 | N6: =IF(J6="Approved",Dashboard!$B$2-K6,"") -> 247 | O6: =IF(AND(J6="Approved",L6="No"),IF(N6>7,"Stale gap","Recent"),"") | P6: =COUNTIFS($C$2:$C$82,C6,$E$2:$E$82,E6,$B$2:$B$82,">="&B6-7,$B$2:$B$82,"<="&B6+7) -> 1 | Q6: =IF(J6="Approved",K6-B6,"") -> 10
A7: RR-26-0006 | B7: 46041 | C7: Paul Mercer | D7: Finance | E7: Financial Analyst | F7: Backfill | G7: Full-time | H7: London | I7: 46104 | J7: Approved | K7: 46055 | L7: =IF(COUNTIF(iCIMS_Export!M:M,A7)>0,"Yes","No") -> Yes | M7: =_xlfn.XLOOKUP(A7,iCIMS_Export!$M$2:$M$57,iCIMS_Export!$A$2:$A$57,"") -> 4104 | N7: =IF(J7="Approved",Dashboard!$B$2-K7,"") -> 240 | O7: =IF(AND(J7="Approved",L7="No"),IF(N7>7,"Stale gap","Recent"),"") | P7: =COUNTIFS($C$2:$C$82,C7,$E$2:$E$82,E7,$B$2:$B$82,">="&B7-7,$B$2:$B$82,"<="&B7+7) -> 1 | Q7: =IF(J7="Approved",K7-B7,"") -> 14
A8: RR-26-0007 | B8: 46042 | C8: Daniel Osei | D8: Product | E8: Product Manager | F8: Backfill | G8: Full-time | H8: Boston | I8: 46115 | J8: Approved | K8: 46055 | L8: =IF(COUNTIF(iCIMS_Export!M:M,A8)>0,"Yes","No") -> Yes | M8: =_xlfn.XLOOKUP(A8,iCIMS_Export!$M$2:$M$57,iCIMS_Export!$A$2:$A$57,"") -> 4105 | N8: =IF(J8="Approved",Dashboard!$B$2-K8,"") -> 240 | O8: =IF(AND(J8="Approved",L8="No"),IF(N8>7,"Stale gap","Recent"),"") | P8: =COUNTIFS($C$2:$C$82,C8,$E$2:$E$82,E8,$B$2:$B$82,">="&B8-7,$B$2:$B$82,"<="&B8+7) -> 1 | Q8: =IF(J8="Approved",K8-B8,"") -> 13
A9: RR-26-0008 | B9: 46044 | C9: Jasmine Reid | D9: Sales | E9: Sales Operations Analyst | F9: Backfill | G9: Full-time | H9: London | I9: 46115 | J9: Approved | K9: 46052 | L9: =IF(COUNTIF(iCIMS_Export!M:M,A9)>0,"Yes","No") -> Yes | M9: =_xlfn.XLOOKUP(A9,iCIMS_Export!$M$2:$M$57,iCIMS_Export!$A$2:$A$57,"") -> 4108 | N9: =IF(J9="Approved",Dashboard!$B$2-K9,"") -> 243 | O9: =IF(AND(J9="Approved",L9="No"),IF(N9>7,"Stale gap","Recent"),"") | P9: =COUNTIFS($C$2:$C$82,C9,$E$2:$E$82,E9,$B$2:$B$82,">="&B9-7,$B$2:$B$82,"<="&B9+7) -> 1 | Q9: =IF(J9="Approved",K9-B9,"") -> 8
A10: RR-26-0009 | B10: 46049 | C10: Carlos Mendes | D10: Sales | E10: Account Executive | F10: New Headcount | G10: Full-time | H10: Boston | I10: 46135 | J10: Approved | K10: 46070 | L10: =IF(COUNTIF(iCIMS_Export!M:M,A10)>0,"Yes","No") -> Yes | M10: =_xlfn.XLOOKUP(A10,iCIMS_Export!$M$2:$M$57,iCIMS_Export!$A$2:$A$57,"") -> 4109 | N10: =IF(J10="Approved",Dashboard!$B$2-K10,"") -> 225 | O10: =IF(AND(J10="Approved",L10="No"),IF(N10>7,"Stale gap","Recent"),"") | P10: =COUNTIFS($C$2:$C$82,C10,$E$2:$E$82,E10,$B$2:$B$82,">="&B10-7,$B$2:$B$82,"<="&B10+7) -> 1 | Q10: =IF(J10="Approved",K10-B10,"") -> 21
A11: RR-26-0010 | B11: 46056 | C11: Grace Holloway | D11: Events | E11: Event Marketing Manager | F11: New Headcount | G11: Full-time | H11: London | I11: 46134 | J11: Approved | K11: 46076 | L11: =IF(COUNTIF(iCIMS_Export!M:M,A11)>0,"Yes","No") -> Yes | M11: =_xlfn.XLOOKUP(A11,iCIMS_Export!$M$2:$M$57,iCIMS_Export!$A$2:$A$57,"") -> 4113 | N11: =IF(J11="Approved",Dashboard!$B$2-K11,"") -> 219 | O11: =IF(AND(J11="Approved",L11="No"),IF(N11>7,"Stale gap","Recent"),"") | P11: =COUNTIFS($C$2:$C$82,C11,$E$2:$E$82,E11,$B$2:$B$82,">="&B11-7,$B$2:$B$82,"<="&B11+7) -> 1 | Q11: =IF(J11="Approved",K11-B11,"") -> 20
A12: RR-26-0011 | B12: 46064 | C12: Olivia Chen | D12: Marketing | E12: Product Marketing Manager | F12: New Headcount | G12: Full-time | H12: Boston | I12: 46141 | J12: Approved | K12: 46073 | L12: =IF(COUNTIF(iCIMS_Export!M:M,A12)>0,"Yes","No") -> Yes | M12: =_xlfn.XLOOKUP(A12,iCIMS_Export!$M$2:$M$57,iCIMS_Export!$A$2:$A$57,"") -> 4110 | N12: =IF(J12="Approved",Dashboard!$B$2-K12,"") -> 222 | O12: =IF(AND(J12="Approved",L12="No"),IF(N12>7,"Stale gap","Recent"),"") | P12: =COUNTIFS($C$2:$C$82,C12,$E$2:$E$82,E12,$B$2:$B$82,">="&B12-7,$B$2:$B$82,"<="&B12+7) -> 1 | Q12: =IF(J12="Approved",K12-B12,"") -> 9
A13: RR-26-0012 | B13: 46076 | C13: Daniel Osei | D13: Product | E13: Senior Product Manager | F13: Backfill | G13: Full-time | H13: London | I13: 46136 | J13: Approved | K13: 46084 | L13: =IF(COUNTIF(iCIMS_Export!M:M,A13)>0,"Yes","No") -> Yes | M13: =_xlfn.XLOOKUP(A13,iCIMS_Export!$M$2:$M$57,iCIMS_Export!$A$2:$A$57,"") -> 4112 | N13: =IF(J13="Approved",Dashboard!$B$2-K13,"") -> 211 | O13: =IF(AND(J13="Approved",L13="No"),IF(N13>7,"Stale gap","Recent"),"") | P13: =COUNTIFS($C$2:$C$82,C13,$E$2:$E$82,E13,$B$2:$B$82,">="&B13-7,$B$2:$B$82,"<="&B13+7) -> 1 | Q13: =IF(J13="Approved",K13-B13,"") -> 8
A14: RR-26-0013 | B14: 46078 | C14: Fatima Hassan | D14: IT | E14: IT Support Specialist | F14: New Headcount | G14: Full-time | H14: Boston | I14: 46141 | J14: Rejected | L14: =IF(COUNTIF(iCIMS_Export!M:M,A14)>0,"Yes","No") -> No | M14: =_xlfn.XLOOKUP(A14,iCIMS_Export!$M$2:$M$57,iCIMS_Export!$A$2:$A$57,"") | N14: =IF(J14="Approved",Dashboard!$B$2-K14,"") | O14: =IF(AND(J14="Approved",L14="No"),IF(N14>7,"Stale gap","Recent"),"") | P14: =COUNTIFS($C$2:$C$82,C14,$E$2:$E$82,E14,$B$2:$B$82,">="&B14-7,$B$2:$B$82,"<="&B14+7) -> 1 | Q14: =IF(J14="Approved",K14-B14,"")
A15: RR-26-0014 | B15: 46084 | C15: Julia Novak | D15: Human Resources | E15: HRIS Analyst | F15: New Headcount | G15: Full-time | H15: Boston | I15: 46162 | J15: Approved | K15: 46097 | L15: =IF(COUNTIF(iCIMS_Export!M:M,A15)>0,"Yes","No") -> Yes | M15: =_xlfn.XLOOKUP(A15,iCIMS_Export!$M$2:$M$57,iCIMS_Export!$A$2:$A$57,"") -> 4115 | N15: =IF(J15="Approved",Dashboard!$B$2-K15,"") -> 198 | O15: =IF(AND(J15="Approved",L15="No"),IF(N15>7,"Stale gap","Recent"),"") | P15: =COUNTIFS($C$2:$C$82,C15,$E$2:$E$82,E15,$B$2:$B$82,">="&B15-7,$B$2:$B$82,"<="&B15+7) -> 1 | Q15: =IF(J15="Approved",K15-B15,"") -> 13
A16: RR-26-0015 | B16: 46084 | C16: Sofia Marino | D16: Consulting | E16: Engagement Manager | F16: Backfill | G16: Full-time | H16: Toronto | I16: 46164 | J16: Approved | K16: 46094 | L16: =IF(COUNTIF(iCIMS_Export!M:M,A16)>0,"Yes","No") -> Yes | M16: =_xlfn.XLOOKUP(A16,iCIMS_Export!$M$2:$M$57,iCIMS_Export!$A$2:$A$57,"") -> 4114 | N16: =IF(J16="Approved",Dashboard!$B$2-K16,"") -> 201 | O16: =IF(AND(J16="Approved",L16="No"),IF(N16>7,"Stale gap","Recent"),"") | P16: =COUNTIFS($C$2:$C$82,C16,$E$2:$E$82,E16,$B$2:$B$82,">="&B16-7,$B$2:$B$82,"<="&B16+7) -> 1 | Q16: =IF(J16="Approved",K16-B16,"") -> 10
A17: RR-26-0016 | B17: 46087 | C17: Amy Sorensen | D17: Data & Analytics | E17: Data Engineer | F17: Backfill | G17: Contract | H17: Boston | I17: 46167 | J17: Approved | K17: 46099 | L17: =IF(COUNTIF(iCIMS_Export!M:M,A17)>0,"Yes","No") -> Yes | M17: =_xlfn.XLOOKUP(A17,iCIMS_Export!$M$2:$M$57,iCIMS_Export!$A$2:$A$57,"") -> 4116 | N17: =IF(J17="Approved",Dashboard!$B$2-K17,"") -> 196 | O17: =IF(AND(J17="Approved",L17="No"),IF(N17>7,"Stale gap","Recent"),"") | P17: =COUNTIFS($C$2:$C$82,C17,$E$2:$E$82,E17,$B$2:$B$82,">="&B17-7,$B$2:$B$82,"<="&B17+7) -> 1 | Q17: =IF(J17="Approved",K17-B17,"") -> 12
A18: RR-26-0017 | B18: 46094 | C18: Lisa Tran | D18: Finance | E18: Senior Accountant | F18: Backfill | G18: Full-time | H18: Boston | I18: 46148 | J18: Approved | K18: 46121 | L18: =IF(COUNTIF(iCIMS_Export!M:M,A18)>0,"Yes","No") -> Yes | M18: =_xlfn.XLOOKUP(A18,iCIMS_Export!$M$2:$M$57,iCIMS_Export!$A$2:$A$57,"") -> 4118 | N18: =IF(J18="Approved",Dashboard!$B$2-K18,"") -> 174 | O18: =IF(AND(J18="Approved",L18="No"),IF(N18>7,"Stale gap","Recent"),"") | P18: =COUNTIFS($C$2:$C$82,C18,$E$2:$E$82,E18,$B$2:$B$82,">="&B18-7,$B$2:$B$82,"<="&B18+7) -> 1 | Q18: =IF(J18="Approved",K18-B18,"") -> 27
A19: RR-26-0018 | B19: 46100 | C19: Michael Grant | D19: Sales | E19: Sales Development Representative | F19: New Headcount | G19: Full-time | H19: Boston | I19: 46188 | J19: Withdrawn | L19: =IF(COUNTIF(iCIMS_Export!M:M,A19)>0,"Yes","No") -> No | M19: =_xlfn.XLOOKUP(A19,iCIMS_Export!$M$2:$M$57,iCIMS_Export!$A$2:$A$57,"") | N19: =IF(J19="Approved",Dashboard!$B$2-K19,"") | O19: =IF(AND(J19="Approved",L19="No"),IF(N19>7,"Stale gap","Recent"),"") | P19: =COUNTIFS($C$2:$C$82,C19,$E$2:$E$82,E19,$B$2:$B$82,">="&B19-7,$B$2:$B$82,"<="&B19+7) -> 1 | Q19: =IF(J19="Approved",K19-B19,"")
A20: RR-26-0019 | B20: 46107 | C20: Jasmine Reid | D20: Sales | E20: Sales Operations Analyst | F20: Backfill | G20: Full-time | H20: Remote (US) | I20: 46197 | J20: Withdrawn | L20: =IF(COUNTIF(iCIMS_Export!M:M,A20)>0,"Yes","No") -> No | M20: =_xlfn.XLOOKUP(A20,iCIMS_Export!$M$2:$M$57,iCIMS_Export!$A$2:$A$57,"") | N20: =IF(J20="Approved",Dashboard!$B$2-K20,"") | O20: =IF(AND(J20="Approved",L20="No"),IF(N20>7,"Stale gap","Recent"),"") | P20: =COUNTIFS($C$2:$C$82,C20,$E$2:$E$82,E20,$B$2:$B$82,">="&B20-7,$B$2:$B$82,"<="&B20+7) -> 1 | Q20: =IF(J20="Approved",K20-B20,"")
A21: RR-26-0020 | B21: 46108 | C21: Grace Holloway | D21: Events | E21: Event Marketing Manager | F21: New Headcount | G21: Full-time | H21: London | I21: 46176 | J21: Approved | K21: 46118 | L21: =IF(COUNTIF(iCIMS_Export!M:M,A21)>0,"Yes","No") -> Yes | M21: =_xlfn.XLOOKUP(A21,iCIMS_Export!$M$2:$M$57,iCIMS_Export!$A$2:$A$57,"") -> 4117 | N21: =IF(J21="Approved",Dashboard!$B$2-K21,"") -> 177 | O21: =IF(AND(J21="Approved",L21="No"),IF(N21>7,"Stale gap","Recent"),"") | P21: =COUNTIFS($C$2:$C$82,C21,$E$2:$E$82,E21,$B$2:$B$82,">="&B21-7,$B$2:$B$82,"<="&B21+7) -> 1 | Q21: =IF(J21="Approved",K21-B21,"") -> 10
A22: RR-26-0021 | B22: 46112 | C22: Nikhil Rao | D22: Data & Analytics | E22: Analytics Engineer | F22: New Headcount | G22: Full-time | H22: Boston | I22: 46199 | J22: Approved | K22: 46133 | L22: =IF(COUNTIF(iCIMS_Export!M:M,A22)>0,"Yes","No") -> Yes | M22: =_xlfn.XLOOKUP(A22,iCIMS_Export!$M$2:$M$57,iCIMS_Export!$A$2:$A$57,"") -> 4120 | N22: =IF(J22="Approved",Dashboard!$B$2-K22,"") -> 162 | O22: =IF(AND(J22="Approved",L22="No"),IF(N22>7,"Stale gap","Recent"),"") | P22: =COUNTIFS($C$2:$C$82,C22,$E$2:$E$82,E22,$B$2:$B$82,">="&B22-7,$B$2:$B$82,"<="&B22+7) -> 1 | Q22: =IF(J22="Approved",K22-B22,"") -> 21
A23: RR-26-0022 | B23: 46114 | C23: Olivia Chen | D23: Marketing | E23: Content Marketing Manager | F23: New Headcount | G23: Full-time | H23: Boston | I23: 46196 | J23: Approved | K23: 46126 | L23: =IF(COUNTIF(iCIMS_Export!M:M,A23)>0,"Yes","No") -> Yes | M23: =_xlfn.XLOOKUP(A23,iCIMS_Export!$M$2:$M$57,iCIMS_Export!$A$2:$A$57,"") -> 4119 | N23: =IF(J23="Approved",Dashboard!$B$2-K23,"") -> 169 | O23: =IF(AND(J23="Approved",L23="No"),IF(N23>7,"Stale gap","Recent"),"") | P23: =COUNTIFS($C$2:$C$82,C23,$E$2:$E$82,E23,$B$2:$B$82,">="&B23-7,$B$2:$B$82,"<="&B23+7) -> 1 | Q23: =IF(J23="Approved",K23-B23,"") -> 12
A24: RR-26-0023 | B24: 46115 | C24: Robert Hayes | D24: Human Resources | E24: Benefits Specialist | F24: New Headcount | G24: Full-time | H24: London | I24: 46195 | J24: Approved | K24: 46136 | L24: =IF(COUNTIF(iCIMS_Export!M:M,A24)>0,"Yes","No") -> Yes | M24: =_xlfn.XLOOKUP(A24,iCIMS_Export!$M$2:$M$57,iCIMS_Export!$A$2:$A$57,"") -> 4122 | N24: =IF(J24="Approved",Dashboard!$B$2-K24,"") -> 159 | O24: =IF(AND(J24="Approved",L24="No"),IF(N24>7,"Stale gap","Recent"),"") | P24: =COUNTIFS($C$2:$C$82,C24,$E$2:$E$82,E24,$B$2:$B$82,">="&B24-7,$B$2:$B$82,"<="&B24+7) -> 1 | Q24: =IF(J24="Approved",K24-B24,"") -> 21
A25: RR-26-0024 | B25: 46115 | C25: Olivia Chen | D25: Marketing | E25: Product Marketing Manager | F25: New Headcount | G25: Full-time | H25: Boston | I25: 46174 | J25: Rejected | L25: =IF(COUNTIF(iCIMS_Export!M:M,A25)>0,"Yes","No") -> No | M25: =_xlfn.XLOOKUP(A25,iCIMS_Export!$M$2:$M$57,iCIMS_Export!$A$2:$A$57,"") | N25: =IF(J25="Approved",Dashboard!$B$2-K25,"") | O25: =IF(AND(J25="Approved",L25="No"),IF(N25>7,"Stale gap","Recent"),"") | P25: =COUNTIFS($C$2:$C$82,C25,$E$2:$E$82,E25,$B$2:$B$82,">="&B25-7,$B$2:$B$82,"<="&B25+7) -> 1 | Q25: =IF(J25="Approved",K25-B25,"")
A26: RR-26-0025 | B26: 46119 | C26: Elena Vasquez | D26: Research | E26: Research Analyst | F26: Backfill | G26: Full-time | H26: Toronto | I26: 46184 | J26: Approved | K26: 46147 | L26: =IF(COUNTIF(iCIMS_Export!M:M,A26)>0,"Yes","No") -> Yes | M26: =_xlfn.XLOOKUP(A26,iCIMS_Export!$M$2:$M$57,iCIMS_Export!$A$2:$A$57,"") -> 4127 | N26: =IF(J26="Approved",Dashboard!$B$2-K26,"") -> 148 | O26: =IF(AND(J26="Approved",L26="No"),IF(N26>7,"Stale gap","Recent"),"") | P26: =COUNTIFS($C$2:$C$82,C26,$E$2:$E$82,E26,$B$2:$B$82,">="&B26-7,$B$2:$B$82,"<="&B26+7) -> 1 | Q26: =IF(J26="Approved",K26-B26,"") -> 28
A27: RR-26-0026 | B27: 46127 | C27: Brian Cho | D27: Research | E27: Research Manager | F27: New Headcount | G27: Full-time | H27: Remote (US) | I27: 46216 | J27: Approved | K27: 46142 | L27: =IF(COUNTIF(iCIMS_Export!M:M,A27)>0,"Yes","No") -> Yes | M27: =_xlfn.XLOOKUP(A27,iCIMS_Export!$M$2:$M$57,iCIMS_Export!$A$2:$A$57,"") -> 4123 | N27: =IF(J27="Approved",Dashboard!$B$2-K27,"") -> 153 | O27: =IF(AND(J27="Approved",L27="No"),IF(N27>7,"Stale gap","Recent"),"") | P27: =COUNTIFS($C$2:$C$82,C27,$E$2:$E$82,E27,$B$2:$B$82,">="&B27-7,$B$2:$B$82,"<="&B27+7) -> 1 | Q27: =IF(J27="Approved",K27-B27,"") -> 15
A28: RR-26-0027 | B28: 46128 | C28: Robert Hayes | D28: Human Resources | E28: HRIS Analyst | F28: New Headcount | G28: Full-time | H28: Boston | I28: 46197 | J28: Approved | K28: 46141 | L28: =IF(COUNTIF(iCIMS_Export!M:M,A28)>0,"Yes","No") -> Yes | M28: =_xlfn.XLOOKUP(A28,iCIMS_Export!$M$2:$M$57,iCIMS_Export!$A$2:$A$57,"") -> 4124 | N28: =IF(J28="Approved",Dashboard!$B$2-K28,"") -> 154 | O28: =IF(AND(J28="Approved",L28="No"),IF(N28>7,"Stale gap","Recent"),"") | P28: =COUNTIFS($C$2:$C$82,C28,$E$2:$E$82,E28,$B$2:$B$82,">="&B28-7,$B$2:$B$82,"<="&B28+7) -> 1 | Q28: =IF(J28="Approved",K28-B28,"") -> 13
A29: RR-26-0028 | B29: 46132 | C29: Fatima Hassan | D29: IT | E29: IT Support Specialist | F29: New Headcount | G29: Full-time | H29: Boston | I29: 46185 | J29: Approved | K29: 46148 | L29: =IF(COUNTIF(iCIMS_Export!M:M,A29)>0,"Yes","No") -> Yes | M29: =_xlfn.XLOOKUP(A29,iCIMS_Export!$M$2:$M$57,iCIMS_Export!$A$2:$A$57,"") -> 4126 | N29: =IF(J29="Approved",Dashboard!$B$2-K29,"") -> 147 | O29: =IF(AND(J29="Approved",L29="No"),IF(N29>7,"Stale gap","Recent"),"") | P29: =COUNTIFS($C$2:$C$82,C29,$E$2:$E$82,E29,$B$2:$B$82,">="&B29-7,$B$2:$B$82,"<="&B29+7) -> 1 | Q29: =IF(J29="Approved",K29-B29,"") -> 16
A30: RR-26-0029 | B30: 46133 | C30: Ethan Park | D30: Marketing | E30: Marketing Operations Specialist | F30: New Headcount | G30: Full-time | H30: Boston | I30: 46196 | J30: Approved | K30: 46142 | L30: =IF(COUNTIF(iCIMS_Export!M:M,A30)>0,"Yes","No") -> Yes | M30: =_xlfn.XLOOKUP(A30,iCIMS_Export!$M$2:$M$57,iCIMS_Export!$A$2:$A$57,"") -> 4121 | N30: =IF(J30="Approved",Dashboard!$B$2-K30,"") -> 153 | O30: =IF(AND(J30="Approved",L30="No"),IF(N30>7,"Stale gap","Recent"),"") | P30: =COUNTIFS($C$2:$C$82,C30,$E$2:$E$82,E30,$B$2:$B$82,">="&B30-7,$B$2:$B$82,"<="&B30+7) -> 1 | Q30: =IF(J30="Approved",K30-B30,"") -> 9
A31: RR-26-0030 | B31: 46136 | C31: Amy Sorensen | D31: Data & Analytics | E31: Analytics Engineer | F31: New Headcount | G31: Full-time | H31: Boston | I31: 46225 | J31: Approved | K31: 46146 | L31: =IF(COUNTIF(iCIMS_Export!M:M,A31)>0,"Yes","No") -> Yes | M31: =_xlfn.XLOOKUP(A31,iCIMS_Export!$M$2:$M$57,iCIMS_Export!$A$2:$A$57,"") -> 4125 | N31: =IF(J31="Approved",Dashboard!$B$2-K31,"") -> 149 | O31: =IF(AND(J31="Approved",L31="No"),IF(N31>7,"Stale gap","Recent"),"") | P31: =COUNTIFS($C$2:$C$82,C31,$E$2:$E$82,E31,$B$2:$B$82,">="&B31-7,$B$2:$B$82,"<="&B31+7) -> 1 | Q31: =IF(J31="Approved",K31-B31,"") -> 10
A32: RR-26-0031 | B32: 46142 | C32: Brian Cho | D32: Research | E32: Senior Research Analyst | F32: New Headcount | G32: Full-time | H32: Boston | I32: 46219 | J32: Withdrawn | L32: =IF(COUNTIF(iCIMS_Export!M:M,A32)>0,"Yes","No") -> No | M32: =_xlfn.XLOOKUP(A32,iCIMS_Export!$M$2:$M$57,iCIMS_Export!$A$2:$A$57,"") | N32: =IF(J32="Approved",Dashboard!$B$2-K32,"") | O32: =IF(AND(J32="Approved",L32="No"),IF(N32>7,"Stale gap","Recent"),"") | P32: =COUNTIFS($C$2:$C$82,C32,$E$2:$E$82,E32,$B$2:$B$82,">="&B32-7,$B$2:$B$82,"<="&B32+7) -> 1 | Q32: =IF(J32="Approved",K32-B32,"")
A33: RR-26-0032 | B33: 46150 | C33: Megan O'Neill | D33: Research | E33: Research Analyst | F33: New Headcount | G33: Full-time | I33: 46204 | J33: Approved | K33: 46160 | L33: =IF(COUNTIF(iCIMS_Export!M:M,A33)>0,"Yes","No") -> Yes | M33: =_xlfn.XLOOKUP(A33,iCIMS_Export!$M$2:$M$57,iCIMS_Export!$A$2:$A$57,"") -> 4128 | N33: =IF(J33="Approved",Dashboard!$B$2-K33,"") -> 135 | O33: =IF(AND(J33="Approved",L33="No"),IF(N33>7,"Stale gap","Recent"),"") | P33: =COUNTIFS($C$2:$C$82,C33,$E$2:$E$82,E33,$B$2:$B$82,">="&B33-7,$B$2:$B$82,"<="&B33+7) -> 1 | Q33: =IF(J33="Approved",K33-B33,"") -> 10
A34: RR-26-0033 | B34: 46156 | C34: Elena Vasquez | D34: Research | E34: Research Analyst | F34: New Headcount | G34: Full-time | H34: Boston | I34: 46241 | J34: Approved | K34: 46170 | L34: =IF(COUNTIF(iCIMS_Export!M:M,A34)>0,"Yes","No") -> Yes | M34: =_xlfn.XLOOKUP(A34,iCIMS_Export!$M$2:$M$57,iCIMS_Export!$A$2:$A$57,"") -> 4129 | N34: =IF(J34="Approved",Dashboard!$B$2-K34,"") -> 125 | O34: =IF(AND(J34="Approved",L34="No"),IF(N34>7,"Stale gap","Recent"),"") | P34: =COUNTIFS($C$2:$C$82,C34,$E$2:$E$82,E34,$B$2:$B$82,">="&B34-7,$B$2:$B$82,"<="&B34+7) -> 1 | Q34: =IF(J34="Approved",K34-B34,"") -> 14
A35: RR-26-0034 | B35: 46161 | C35: Sofia Marino | D35: Consulting | E35: Senior Consultant | F35: New Headcount | G35: Full-time | H35: Boston | I35: 46227 | J35: Approved | K35: 46169 | L35: =IF(COUNTIF(iCIMS_Export!M:M,A35)>0,"Yes","No") -> Yes | M35: =_xlfn.XLOOKUP(A35,iCIMS_Export!$M$2:$M$57,iCIMS_Export!$A$2:$A$57,"") -> 4132 | N35: =IF(J35="Approved",Dashboard!$B$2-K35,"") -> 126 | O35: =IF(AND(J35="Approved",L35="No"),IF(N35>7,"Stale gap","Recent"),"") | P35: =COUNTIFS($C$2:$C$82,C35,$E$2:$E$82,E35,$B$2:$B$82,">="&B35-7,$B$2:$B$82,"<="&B35+7) -> 1 | Q35: =IF(J35="Approved",K35-B35,"") -> 8
A36: RR-26-0035 | B36: 46164 | C36: Kevin Doyle | D36: IT | E36: Systems Administrator | F36: Backfill | G36: Full-time | H36: Boston | I36: 46251 | J36: Rejected | L36: =IF(COUNTIF(iCIMS_Export!M:M,A36)>0,"Yes","No") -> No | M36: =_xlfn.XLOOKUP(A36,iCIMS_Export!$M$2:$M$57,iCIMS_Export!$A$2:$A$57,"") | N36: =IF(J36="Approved",Dashboard!$B$2-K36,"") | O36: =IF(AND(J36="Approved",L36="No"),IF(N36>7,"Stale gap","Recent"),"") | P36: =COUNTIFS($C$2:$C$82,C36,$E$2:$E$82,E36,$B$2:$B$82,">="&B36-7,$B$2:$B$82,"<="&B36+7) -> 1 | Q36: =IF(J36="Approved",K36-B36,"")
A37: RR-26-0036 | B37: 46164 | C37: Carlos Mendes | D37: Sales | E37: Sales Development Representative | F37: Backfill | G37: Full-time | H37: Boston | I37: 46232 | J37: Approved | K37: 46178 | L37: =IF(COUNTIF(iCIMS_Export!M:M,A37)>0,"Yes","No") -> Yes | M37: =_xlfn.XLOOKUP(A37,iCIMS_Export!$M$2:$M$57,iCIMS_Export!$A$2:$A$57,"") -> 4130 | N37: =IF(J37="Approved",Dashboard!$B$2-K37,"") -> 117 | O37: =IF(AND(J37="Approved",L37="No"),IF(N37>7,"Stale gap","Recent"),"") | P37: =COUNTIFS($C$2:$C$82,C37,$E$2:$E$82,E37,$B$2:$B$82,">="&B37-7,$B$2:$B$82,"<="&B37+7) -> 1 | Q37: =IF(J37="Approved",K37-B37,"") -> 14
A38: RR-26-0037 | B38: 46170 | C38: Elena Vasquez | D38: Research | E38: Senior Research Analyst | F38: Backfill | G38: Full-time | H38: Boston | I38: 46239 | J38: Approved | K38: 46181 | L38: =IF(COUNTIF(iCIMS_Export!M:M,A38)>0,"Yes","No") -> Yes | M38: =_xlfn.XLOOKUP(A38,iCIMS_Export!$M$2:$M$57,iCIMS_Export!$A$2:$A$57,"") -> 4131 | N38: =IF(J38="Approved",Dashboard!$B$2-K38,"") -> 114 | O38: =IF(AND(J38="Approved",L38="No"),IF(N38>7,"Stale gap","Recent"),"") | P38: =COUNTIFS($C$2:$C$82,C38,$E$2:$E$82,E38,$B$2:$B$82,">="&B38-7,$B$2:$B$82,"<="&B38+7) -> 1 | Q38: =IF(J38="Approved",K38-B38,"") -> 11
A39: RR-26-0038 | B39: 46176 | C39: Ethan Park | D39: Marketing | E39: Digital Marketing Analyst | F39: New Headcount | G39: Full-time | I39: 46246 | J39: Approved | K39: 46188 | L39: =IF(COUNTIF(iCIMS_Export!M:M,A39)>0,"Yes","No") -> Yes | M39: =_xlfn.XLOOKUP(A39,iCIMS_Export!$M$2:$M$57,iCIMS_Export!$A$2:$A$57,"") -> 4134 | N39: =IF(J39="Approved",Dashboard!$B$2-K39,"") -> 107 | O39: =IF(AND(J39="Approved",L39="No"),IF(N39>7,"Stale gap","Recent"),"") | P39: =COUNTIFS($C$2:$C$82,C39,$E$2:$E$82,E39,$B$2:$B$82,">="&B39-7,$B$2:$B$82,"<="&B39+7) -> 1 | Q39: =IF(J39="Approved",K39-B39,"") -> 12
A40: RR-26-0039 | B40: 46181 | C40: Jasmine Reid | D40: Sales | E40: Account Manager | F40: New Headcount | G40: Full-time | H40: Boston | I40: 46234 | J40: Approved | K40: 46195 | L40: =IF(COUNTIF(iCIMS_Export!M:M,A40)>0,"Yes","No") -> No | M40: =_xlfn.XLOOKUP(A40,iCIMS_Export!$M$2:$M$57,iCIMS_Export!$A$2:$A$57,"") | N40: =IF(J40="Approved",Dashboard!$B$2-K40,"") -> 100 | O40: =IF(AND(J40="Approved",L40="No"),IF(N40>7,"Stale gap","Recent"),"") -> Stale gap | P40: =COUNTIFS($C$2:$C$82,C40,$E$2:$E$82,E40,$B$2:$B$82,">="&B40-7,$B$2:$B$82,"<="&B40+7) -> 1 | Q40: =IF(J40="Approved",K40-B40,"") -> 14
...

Sheet Approvals_Log
A1: Request ID | B1: Step | C1: Approver | D1: Received On | E1: Decided On | F1: Decision | G1: Days_In_Step
A2: RR-26-0001 | B2: 1 - Dept Head | C2: Samuel Adeyemi | D2: 46027 | E2: 46029 | F2: Approved | G2: =IF(F2="Pending",Dashboard!$B$2-D2,E2-D2) -> 2
A3: RR-26-0001 | B3: 2 - Finance | C3: Anita Desai | D3: 46029 | E3: 46044 | F3: Approved | G3: =IF(F3="Pending",Dashboard!$B$2-D3,E3-D3) -> 15
A4: RR-26-0001 | B4: 3 - HR Business Partner | C4: Tessa Nguyen | D4: 46044 | E4: 46048 | F4: Approved | G4: =IF(F4="Pending",Dashboard!$B$2-D4,E4-D4) -> 4
A5: RR-26-0002 | B5: 1 - Dept Head | C5: Laura Whitfield | D5: 46030 | E5: 46030 | F5: Approved | G5: =IF(F5="Pending",Dashboard!$B$2-D5,E5-D5) -> 0
A6: RR-26-0002 | B6: 2 - Finance | C6: Anita Desai | D6: 46030 | E6: 46042 | F6: Approved | G6: =IF(F6="Pending",Dashboard!$B$2-D6,E6-D6) -> 12
A7: RR-26-0002 | B7: 3 - HR Business Partner | C7: Monica Alvarez | D7: 46042 | E7: 46043 | F7: Approved | G7: =IF(F7="Pending",Dashboard!$B$2-D7,E7-D7) -> 1
A8: RR-26-0003 | B8: 1 - Dept Head | C8: Diane Kowalski | D8: 46035 | E8: 46037 | F8: Approved | G8: =IF(F8="Pending",Dashboard!$B$2-D8,E8-D8) -> 2
A9: RR-26-0003 | B9: 2 - Finance | C9: Gary Whitman | D9: 46037 | E9: 46041 | F9: Approved | G9: =IF(F9="Pending",Dashboard!$B$2-D9,E9-D9) -> 4
A10: RR-26-0003 | B10: 3 - HR Business Partner | C10: Jordan Blake | D10: 46041 | E10: 46045 | F10: Approved | G10: =IF(F10="Pending",Dashboard!$B$2-D10,E10-D10) -> 4
A11: RR-26-0004 | B11: 1 - Dept Head | C11: Diane Kowalski | D11: 46037 | E11: 46041 | F11: Approved | G11: =IF(F11="Pending",Dashboard!$B$2-D11,E11-D11) -> 4
A12: RR-26-0004 | B12: 2 - Finance | C12: Gary Whitman | D12: 46041 | E12: 46044 | F12: Approved | G12: =IF(F12="Pending",Dashboard!$B$2-D12,E12-D12) -> 3
A13: RR-26-0004 | B13: 3 - HR Business Partner | C13: Jordan Blake | D13: 46044 | E13: 46048 | F13: Approved | G13: =IF(F13="Pending",Dashboard!$B$2-D13,E13-D13) -> 4
... A183: RR-26-0066 | B183: 1 - Dept Head | C183: Laura Whitfield | D183: 46269 | E183: 46274 | F183: Approved | G183: =IF(F183="Pending",Dashboard!$B$2-D183,E183-D183) -> 5
A184: RR-26-0066 | B184: 2 - Finance | C184: Gary Whitman | D184: 46274 | F184: Pending | G184: =IF(F184="Pending",Dashboard!$B$2-D184,E184-D184) -> 21
A185: RR-26-0067 | B185: 1 - Dept Head | C185: Samuel Adeyemi | D185: 46274 | E185: 46279 | F185: Approved | G185: =IF(F185="Pending",Dashboard!$B$2-D185,E185-D185) -> 5
A186: RR-26-0067 | B186: 2 - Finance | C186: Gary Whitman | D186: 46279 | F186: Pending | G186: =IF(F186="Pending",Dashboard!$B$2-D186,E186-D186) -> 16
A187: RR-26-0068 | B187: 1 - Dept Head | C187: Samuel Adeyemi | D187: 46275 | E187: 46276 | F187: Approved | G187: =IF(F187="Pending",Dashboard!$B$2-D187,E187-D187) -> 1
A188: RR-26-0068 | B188: 2 - Finance | C188: Anita Desai | D188: 46276 | F188: Pending | G188: =IF(F188="Pending",Dashboard!$B$2-D188,E188-D188) -> 19
A189: RR-26-0069 | B189: 1 - Dept Head | C189: Diane Kowalski | D189: 46275 | E189: 46275 | F189: Approved | G189: =IF(F189="Pending",Dashboard!$B$2-D189,E189-D189) -> 0
A190: RR-26-0069 | B190: 2 - Finance | C190: Anita Desai | D190: 46275 | E190: 46280 | F190: Approved | G190: =IF(F190="Pending",Dashboard!$B$2-D190,E190-D190) -> 5
A191: RR-26-0069 | B191: 3 - HR Business Partner | C191: Jordan Blake | D191: 46280 | E191: 46282 | F191: Approved | G191: =IF(F191="Pending",Dashboard!$B$2-D191,E191-D191) -> 2
A192: RR-26-0070 | B192: 1 - Dept Head | C192: Tom Brennan | D192: 46279 | E192: 46280 | F192: Approved | G192: =IF(F192="Pending",Dashboard!$B$2-D192,E192-D192) -> 1
A193: RR-26-0070 | B193: 2 - Finance | C193: Anita Desai | D193: 46280 | E193: 46286 | F193: Approved | G193: =IF(F193="Pending",Dashboard!$B$2-D193,E193-D193) -> 6
A194: RR-26-0070 | B194: 3 - HR Business Partner | C194: Jordan Blake | D194: 46286 | E194: 46288 | F194: Approved | G194: =IF(F194="Pending",Dashboard!$B$2-D194,E194-D194) -> 2
A195: RR-26-0071 | B195: 1 - Dept Head | C195: Aaron Feld | D195: 46279 | E195: 46282 | F195: Approved | G195: =IF(F195="Pending",Dashboard!$B$2-D195,E195-D195) -> 3
A196: RR-26-0071 | B196: 2 - Finance | C196: Anita Desai | D196: 46282 | E196: 46287 | F196: Approved | G196: =IF(F196="Pending",Dashboard!$B$2-D196,E196-D196) -> 5
A197: RR-26-0071 | B197: 3 - HR Business Partner | C197: Monica Alvarez | D197: 46287 | E197: 46288 | F197: Approved | G197: =IF(F197="Pending",Dashboard!$B$2-D197,E197-D197) -> 1
A198: RR-26-0072 | B198: 1 - Dept Head | C198: Diane Kowalski | D198: 46279 | E198: 46283 | F198: Approved | G198: =IF(F198="Pending",Dashboard!$B$2-D198,E198-D198) -> 4
A199: RR-26-0072 | B199: 2 - Finance | C199: Anita Desai | D199: 46283 | E199: 46286 | F199: Approved | G199: =IF(F199="Pending",Dashboard!$B$2-D199,E199-D199) -> 3
A200: RR-26-0072 | B200: 3 - HR Business Partner | C200: Jordan Blake | D200: 46286 | F200: Pending | G200: =IF(F200="Pending",Dashboard!$B$2-D200,E200-D200) -> 9
A201: RR-26-0073 | B201: 1 - Dept Head | C201: Priya Raman | D201: 46280 | E201: 46283 | F201: Approved | G201: =IF(F201="Pending",Dashboard!$B$2-D201,E201-D201) -> 3
A202: RR-26-0073 | B202: 2 - Finance | C202: Anita Desai | D202: 46283 | F202: Pending | G202: =IF(F202="Pending",Dashboard!$B$2-D202,E202-D202) -> 12
A203: RR-26-0074 | B203: 1 - Dept Head | C203: Aaron Feld | D203: 46280 | F203: Pending | G203: =IF(F203="Pending",Dashboard!$B$2-D203,E203-D203) -> 15
A204: RR-26-0075 | B204: 1 - Dept Head | C204: Rachel Stein | D204: 46283 | E204: 46286 | F204: Approved | G204: =IF(F204="Pending",Dashboard!$B$2-D204,E204-D204) -> 3
A205: RR-26-0075 | B205: 2 - Finance | C205: Gary Whitman | D205: 46286 | E205: 46289 | F205: Approved | G205: =IF(F205="Pending",Dashboard!$B$2-D205,E205-D205) -> 3
A206: RR-26-0075 | B206: 3 - HR Business Partner | C206: Tessa Nguyen | D206: 46289 | E206: 46290 | F206: Approved | G206: =IF(F206="Pending",Dashboard!$B$2-D206,E206-D206) -> 1
A207: RR-26-0076 | B207: 1 - Dept Head | C207: Kenji Watanabe | D207: 46287 | E207: 46290 | F207: Approved | G207: =IF(F207="Pending",Dashboard!$B$2-D207,E207-D207) -> 3
A208: RR-26-0076 | B208: 2 - Finance | C208: Gary Whitman | D208: 46290 | E208: 46294 | F208: Approved | G208: =IF(F208="Pending",Dashboard!$B$2-D208,E208-D208) -> 4
A209: RR-26-0076 | B209: 3 - HR Business Partner | C209: Tessa Nguyen | D209: 46294 | F209: Pending | G209: =IF(F209="Pending",Dashboard!$B$2-D209,E209-D209) -> 1
...

Sheet iCIMS_Export
A1: Job ID | B1: Request Ref | C1: Job Title | D1: Department | E1: Hiring Manager | F1: Recruiter | G1: Location | H1: Date Opened | I1: Status | J1: Offer Accepted Date | K1: Source of Hire | L1: Applicants | M1: Clean_Ref | N1: Site_Status | O1: Req_Flag | P1: Site_Title | Q1: Title_Match | R1: Site_Manager | S1: Manager_Match | T1: Site_Dept | U1: Dept_Match | V1: Opened_Clean | W1: Handoff_Days | X1: Time_To_Fill | Y1: Dept_Clean
A2: 4101 | B2: RR-26-0002 | C2: Research Director | D2: Research | E2: Elena Vasquez | F2: Chris Palmer | G2: Remote (US) | H2: 46044 | I2: Filled | J2: 46076 | K2: Careers Site | L2: 45 | M2: =TRIM(SUBSTITUTE(B2,CHAR(160),"")) -> RR-26-0002 | N2: =IF(M2="","Not found",_xlfn.XLOOKUP(M2,ReqSite_Export!$A$2:$A$82,ReqSite_Export!$J$2:$J$82,"Not found")) -> Approved | O2: =IF(N2="Not found","No request on file",IF(N2<>"Approved","Opened before approval","OK")) -> OK | P2: =IF(N2="Not found","",_xlfn.XLOOKUP(M2,ReqSite_Export!$A$2:$A$82,ReqSite_Export!$E$2:$E$82,"")) -> Research Director | Q2: =IF(P2="","",TRIM(C2)=TRIM(P2)) -> TRUE | R2: =IF(N2="Not found","",_xlfn.XLOOKUP(M2,ReqSite_Export!$A$2:$A$82,ReqSite_Export!$C$2:$C$82,"")) -> Elena Vasquez | S2: =IF(R2="","",TRIM(E2)=TRIM(R2)) -> TRUE | T2: =IF(N2="Not found","",_xlfn.XLOOKUP(M2,ReqSite_Export!$A$2:$A$82,ReqSite_Export!$D$2:$D$82,"")) -> Research | U2: =IF(T2="","",TRIM(D2)=_xlfn.XLOOKUP(T2,Dept_Map!$A$2:$A$11,Dept_Map!$B$2:$B$11,"")) -> TRUE | V2: =IF(ISTEXT(H2),DATEVALUE(H2),H2) -> 46044 | W2: =IF(N2<>"Approved","",V2-_xlfn.XLOOKUP(M2,ReqSite_Export!$A$2:$A$82,ReqSite_Export!$K$2:$K$82)) -> 1 | X2: =IF(AND(I2="Filled",N2="Approved"),J2-_xlfn.XLOOKUP(M2,ReqSite_Export!$A$2:$A$82,ReqSite_Export!$K$2:$K$82),"") -> 33 | Y2: =TRIM(D2) -> Research
A3: 4102 | B3: RR-26-0003 | C3: Sales Operations Analyst | D3: Sales | E3: Carlos Mendes | F3: Dana Whitaker | G3: London | H3: 46048 | I3: Filled | J3: 46087 | K3: Careers Site | L3: 62 | M3: =TRIM(SUBSTITUTE(B3,CHAR(160),"")) -> RR-26-0003 | N3: =IF(M3="","Not found",_xlfn.XLOOKUP(M3,ReqSite_Export!$A$2:$A$82,ReqSite_Export!$J$2:$J$82,"Not found")) -> Approved | O3: =IF(N3="Not found","No request on file",IF(N3<>"Approved","Opened before approval","OK")) -> OK | P3: =IF(N3="Not found","",_xlfn.XLOOKUP(M3,ReqSite_Export!$A$2:$A$82,ReqSite_Export!$E$2:$E$82,"")) -> Sales Operations Analyst | Q3: =IF(P3="","",TRIM(C3)=TRIM(P3)) -> TRUE | R3: =IF(N3="Not found","",_xlfn.XLOOKUP(M3,ReqSite_Export!$A$2:$A$82,ReqSite_Export!$C$2:$C$82,"")) -> Carlos Mendes | S3: =IF(R3="","",TRIM(E3)=TRIM(R3)) -> TRUE | T3: =IF(N3="Not found","",_xlfn.XLOOKUP(M3,ReqSite_Export!$A$2:$A$82,ReqSite_Export!$D$2:$D$82,"")) -> Sales | U3: =IF(T3="","",TRIM(D3)=_xlfn.XLOOKUP(T3,Dept_Map!$A$2:$A$11,Dept_Map!$B$2:$B$11,"")) -> TRUE | V3: =IF(ISTEXT(H3),DATEVALUE(H3),H3) -> 46048 | W3: =IF(N3<>"Approved","",V3-_xlfn.XLOOKUP(M3,ReqSite_Export!$A$2:$A$82,ReqSite_Export!$K$2:$K$82)) -> 3 | X3: =IF(AND(I3="Filled",N3="Approved"),J3-_xlfn.XLOOKUP(M3,ReqSite_Export!$A$2:$A$82,ReqSite_Export!$K$2:$K$82),"") -> 42 | Y3: =TRIM(D3) -> Sales
A4: 4103 | B4: RR-26-0001 | C4: Systems Administrator | D4: Information Technology | E4: Kevin Doyle | F4: Imani Brooks | G4: London | H4: 46050 | I4: Filled | J4: 46079 | K4: Internal Move | L4: 60 | M4: =TRIM(SUBSTITUTE(B4,CHAR(160),"")) -> RR-26-0001 | N4: =IF(M4="","Not found",_xlfn.XLOOKUP(M4,ReqSite_Export!$A$2:$A$82,ReqSite_Export!$J$2:$J$82,"Not found")) -> Approved | O4: =IF(N4="Not found","No request on file",IF(N4<>"Approved","Opened before approval","OK")) -> OK | P4: =IF(N4="Not found","",_xlfn.XLOOKUP(M4,ReqSite_Export!$A$2:$A$82,ReqSite_Export!$E$2:$E$82,"")) -> Systems Administrator | Q4: =IF(P4="","",TRIM(C4)=TRIM(P4)) -> TRUE | R4: =IF(N4="Not found","",_xlfn.XLOOKUP(M4,ReqSite_Export!$A$2:$A$82,ReqSite_Export!$C$2:$C$82,"")) -> Kevin Doyle | S4: =IF(R4="","",TRIM(E4)=TRIM(R4)) -> TRUE | T4: =IF(N4="Not found","",_xlfn.XLOOKUP(M4,ReqSite_Export!$A$2:$A$82,ReqSite_Export!$D$2:$D$82,"")) -> IT | U4: =IF(T4="","",TRIM(D4)=_xlfn.XLOOKUP(T4,Dept_Map!$A$2:$A$11,Dept_Map!$B$2:$B$11,"")) -> TRUE | V4: =IF(ISTEXT(H4),DATEVALUE(H4),H4) -> 46050 | W4: =IF(N4<>"Approved","",V4-_xlfn.XLOOKUP(M4,ReqSite_Export!$A$2:$A$82,ReqSite_Export!$K$2:$K$82)) -> 2 | X4: =IF(AND(I4="Filled",N4="Approved"),J4-_xlfn.XLOOKUP(M4,ReqSite_Export!$A$2:$A$82,ReqSite_Export!$K$2:$K$82),"") -> 31 | Y4: =TRIM(D4) -> Information Technology
A5: 4104 | B5: RR-26-0006 | C5: Financial Analyst | D5: Finance | E5: Paul Mercer | F5: Owen Fitzgerald | G5: London | H5: 46055 | I5: Filled | J5: 46127 | K5: Employee Referral | L5: 42 | M5: =TRIM(SUBSTITUTE(B5,CHAR(160),"")) -> RR-26-0006 | N5: =IF(M5="","Not found",_xlfn.XLOOKUP(M5,ReqSite_Export!$A$2:$A$82,ReqSite_Export!$J$2:$J$82,"Not found")) -> Approved | O5: =IF(N5="Not found","No request on file",IF(N5<>"Approved","Opened before approval","OK")) -> OK | P5: =IF(N5="Not found","",_xlfn.XLOOKUP(M5,ReqSite_Export!$A$2:$A$82,ReqSite_Export!$E$2:$E$82,"")) -> Financial Analyst | Q5: =IF(P5="","",TRIM(C5)=TRIM(P5)) -> TRUE | R5: =IF(N5="Not found","",_xlfn.XLOOKUP(M5,ReqSite_Export!$A$2:$A$82,ReqSite_Export!$C$2:$C$82,"")) -> Paul Mercer | S5: =IF(R5="","",TRIM(E5)=TRIM(R5)) -> TRUE | T5: =IF(N5="Not found","",_xlfn.XLOOKUP(M5,ReqSite_Export!$A$2:$A$82,ReqSite_Export!$D$2:$D$82,"")) -> Finance | U5: =IF(T5="","",TRIM(D5)=_xlfn.XLOOKUP(T5,Dept_Map!$A$2:$A$11,Dept_Map!$B$2:$B$11,"")) -> TRUE | V5: =IF(ISTEXT(H5),DATEVALUE(H5),H5) -> 46055 | W5: =IF(N5<>"Approved","",V5-_xlfn.XLOOKUP(M5,ReqSite_Export!$A$2:$A$82,ReqSite_Export!$K$2:$K$82)) -> 0 | X5: =IF(AND(I5="Filled",N5="Approved"),J5-_xlfn.XLOOKUP(M5,ReqSite_Export!$A$2:$A$82,ReqSite_Export!$K$2:$K$82),"") -> 72 | Y5: =TRIM(D5) -> Finance
A6: 4105 | B6: RR-26-0007 | C6: Product Manager | D6: Product Mgmt | E6: Daniel Osei | F6: Imani Brooks | G6: Boston | H6: 46058 | I6: Filled | J6: 46113 | K6: Internal Move | L6: 44 | M6: =TRIM(SUBSTITUTE(B6,CHAR(160),"")) -> RR-26-0007 | N6: =IF(M6="","Not found",_xlfn.XLOOKUP(M6,ReqSite_Export!$A$2:$A$82,ReqSite_Export!$J$2:$J$82,"Not found")) -> Approved | O6: =IF(N6="Not found","No request on file",IF(N6<>"Approved","Opened before approval","OK")) -> OK | P6: =IF(N6="Not found","",_xlfn.XLOOKUP(M6,ReqSite_Export!$A$2:$A$82,ReqSite_Export!$E$2:$E$82,"")) -> Product Manager | Q6: =IF(P6="","",TRIM(C6)=TRIM(P6)) -> TRUE | R6: =IF(N6="Not found","",_xlfn.XLOOKUP(M6,ReqSite_Export!$A$2:$A$82,ReqSite_Export!$C$2:$C$82,"")) -> Daniel Osei | S6: =IF(R6="","",TRIM(E6)=TRIM(R6)) -> TRUE | T6: =IF(N6="Not found","",_xlfn.XLOOKUP(M6,ReqSite_Export!$A$2:$A$82,ReqSite_Export!$D$2:$D$82,"")) -> Product | U6: =IF(T6="","",TRIM(D6)=_xlfn.XLOOKUP(T6,Dept_Map!$A$2:$A$11,Dept_Map!$B$2:$B$11,"")) -> TRUE | V6: =IF(ISTEXT(H6),DATEVALUE(H6),H6) -> 46058 | W6: =IF(N6<>"Approved","",V6-_xlfn.XLOOKUP(M6,ReqSite_Export!$A$2:$A$82,ReqSite_Export!$K$2:$K$82)) -> 3 | X6: =IF(AND(I6="Filled",N6="Approved"),J6-_xlfn.XLOOKUP(M6,ReqSite_Export!$A$2:$A$82,ReqSite_Export!$K$2:$K$82),"") -> 58 | Y6: =TRIM(D6) -> Product Mgmt
A7: 4106 | B7: RR-26-0004 | C7: Account Executive | D7: Sales | E7: Michael Grant | F7: Dana Whitaker | G7: Boston | H7: 46064 | I7: Filled | J7: 46106 | K7: LinkedIn | L7: 75 | M7: =TRIM(SUBSTITUTE(B7,CHAR(160),"")) -> RR-26-0004 | N7: =IF(M7="","Not found",_xlfn.XLOOKUP(M7,ReqSite_Export!$A$2:$A$82,ReqSite_Export!$J$2:$J$82,"Not found")) -> Approved | O7: =IF(N7="Not found","No request on file",IF(N7<>"Approved","Opened before approval","OK")) -> OK | P7: =IF(N7="Not found","",_xlfn.XLOOKUP(M7,ReqSite_Export!$A$2:$A$82,ReqSite_Export!$E$2:$E$82,"")) -> Account Executive | Q7: =IF(P7="","",TRIM(C7)=TRIM(P7)) -> TRUE | R7: =IF(N7="Not found","",_xlfn.XLOOKUP(M7,ReqSite_Export!$A$2:$A$82,ReqSite_Export!$C$2:$C$82,"")) -> Michael Grant | S7: =IF(R7="","",TRIM(E7)=TRIM(R7)) -> TRUE | T7: =IF(N7="Not found","",_xlfn.XLOOKUP(M7,ReqSite_Export!$A$2:$A$82,ReqSite_Export!$D$2:$D$82,"")) -> Sales | U7: =IF(T7="","",TRIM(D7)=_xlfn.XLOOKUP(T7,Dept_Map!$A$2:$A$11,Dept_Map!$B$2:$B$11,"")) -> TRUE | V7: =IF(ISTEXT(H7),DATEVALUE(H7),H7) -> 46064 | W7: =IF(N7<>"Approved","",V7-_xlfn.XLOOKUP(M7,ReqSite_Export!$A$2:$A$82,ReqSite_Export!$K$2:$K$82)) -> 16 | X7: =IF(AND(I7="Filled",N7="Approved"),J7-_xlfn.XLOOKUP(M7,ReqSite_Export!$A$2:$A$82,ReqSite_Export!$K$2:$K$82),"") -> 58 | Y7: =TRIM(D7) -> Sales
A8: 4107 | B8: RR-26-0005 | C8: Event Coordinator | D8: Events | E8: Victor Salgado | F8: Dana Whitaker | G8: London | H8: 46064 | I8: Filled | J8: 46125 | K8: LinkedIn | L8: 41 | M8: =TRIM(SUBSTITUTE(B8,CHAR(160),"")) -> RR-26-0005 | N8: =IF(M8="","Not found",_xlfn.XLOOKUP(M8,ReqSite_Export!$A$2:$A$82,ReqSite_Export!$J$2:$J$82,"Not found")) -> Approved | O8: =IF(N8="Not found","No request on file",IF(N8<>"Approved","Opened before approval","OK")) -> OK | P8: =IF(N8="Not found","",_xlfn.XLOOKUP(M8,ReqSite_Export!$A$2:$A$82,ReqSite_Export!$E$2:$E$82,"")) -> Event Coordinator | Q8: =IF(P8="","",TRIM(C8)=TRIM(P8)) -> TRUE | R8: =IF(N8="Not found","",_xlfn.XLOOKUP(M8,ReqSite_Export!$A$2:$A$82,ReqSite_Export!$C$2:$C$82,"")) -> Victor Salgado | S8: =IF(R8="","",TRIM(E8)=TRIM(R8)) -> TRUE | T8: =IF(N8="Not found","",_xlfn.XLOOKUP(M8,ReqSite_Export!$A$2:$A$82,ReqSite_Export!$D$2:$D$82,"")) -> Events | U8: =IF(T8="","",TRIM(D8)=_xlfn.XLOOKUP(T8,Dept_Map!$A$2:$A$11,Dept_Map!$B$2:$B$11,"")) -> TRUE | V8: =IF(ISTEXT(H8),DATEVALUE(H8),H8) -> 46064 | W8: =IF(N8<>"Approved","",V8-_xlfn.XLOOKUP(M8,ReqSite_Export!$A$2:$A$82,ReqSite_Export!$K$2:$K$82)) -> 16 | X8: =IF(AND(I8="Filled",N8="Approved"),J8-_xlfn.XLOOKUP(M8,ReqSite_Export!$A$2:$A$82,ReqSite_Export!$K$2:$K$82),"") -> 77 | Y8: =TRIM(D8) -> Events
A9: 4108 | B9: RR-26-0008 | C9: Sales Operations Analyst | D9: Sales | E9: Jasmine Reid | F9: Dana Whitaker | G9: London | H9: 46066 | I9: Filled | J9: 46136 | K9: Employee Referral | L9: 31 | M9: =TRIM(SUBSTITUTE(B9,CHAR(160),"")) -> RR-26-0008 | N9: =IF(M9="","Not found",_xlfn.XLOOKUP(M9,ReqSite_Export!$A$2:$A$82,ReqSite_Export!$J$2:$J$82,"Not found")) -> Approved | O9: =IF(N9="Not found","No request on file",IF(N9<>"Approved","Opened before approval","OK")) -> OK | P9: =IF(N9="Not found","",_xlfn.XLOOKUP(M9,ReqSite_Export!$A$2:$A$82,ReqSite_Export!$E$2:$E$82,"")) -> Sales Operations Analyst | Q9: =IF(P9="","",TRIM(C9)=TRIM(P9)) -> TRUE | R9: =IF(N9="Not found","",_xlfn.XLOOKUP(M9,ReqSite_Export!$A$2:$A$82,ReqSite_Export!$C$2:$C$82,"")) -> Jasmine Reid | S9: =IF(R9="","",TRIM(E9)=TRIM(R9)) -> TRUE | T9: =IF(N9="Not found","",_xlfn.XLOOKUP(M9,ReqSite_Export!$A$2:$A$82,ReqSite_Export!$D$2:$D$82,"")) -> Sales | U9: =IF(T9="","",TRIM(D9)=_xlfn.XLOOKUP(T9,Dept_Map!$A$2:$A$11,Dept_Map!$B$2:$B$11,"")) -> TRUE | V9: =IF(ISTEXT(H9),DATEVALUE(H9),H9) -> 46066 | W9: =IF(N9<>"Approved","",V9-_xlfn.XLOOKUP(M9,ReqSite_Export!$A$2:$A$82,ReqSite_Export!$K$2:$K$82)) -> 14 | X9: =IF(AND(I9="Filled",N9="Approved"),J9-_xlfn.XLOOKUP(M9,ReqSite_Export!$A$2:$A$82,ReqSite_Export!$K$2:$K$82),"") -> 84 | Y9: =TRIM(D9) -> Sales
A10: 4109 | B10: RR-26-0009 | C10: Account Executive | D10: Sales | E10: Carlos Mendes | F10: Dana Whitaker | G10: Boston | H10: 46076 | I10: Filled | J10: 46132 | K10: Agency | L10: 54 | M10: =TRIM(SUBSTITUTE(B10,CHAR(160),"")) -> RR-26-0009 | N10: =IF(M10="","Not found",_xlfn.XLOOKUP(M10,ReqSite_Export!$A$2:$A$82,ReqSite_Export!$J$2:$J$82,"Not found")) -> Approved | O10: =IF(N10="Not found","No request on file",IF(N10<>"Approved","Opened before approval","OK")) -> OK | P10: =IF(N10="Not found","",_xlfn.XLOOKUP(M10,ReqSite_Export!$A$2:$A$82,ReqSite_Export!$E$2:$E$82,"")) -> Account Executive | Q10: =IF(P10="","",TRIM(C10)=TRIM(P10)) -> TRUE | R10: =IF(N10="Not found","",_xlfn.XLOOKUP(M10,ReqSite_Export!$A$2:$A$82,ReqSite_Export!$C$2:$C$82,"")) -> Carlos Mendes | S10: =IF(R10="","",TRIM(E10)=TRIM(R10)) -> TRUE | T10: =IF(N10="Not found","",_xlfn.XLOOKUP(M10,ReqSite_Export!$A$2:$A$82,ReqSite_Export!$D$2:$D$82,"")) -> Sales | U10: =IF(T10="","",TRIM(D10)=_xlfn.XLOOKUP(T10,Dept_Map!$A$2:$A$11,Dept_Map!$B$2:$B$11,"")) -> TRUE | V10: =IF(ISTEXT(H10),DATEVALUE(H10),H10) -> 46076 | W10: =IF(N10<>"Approved","",V10-_xlfn.XLOOKUP(M10,ReqSite_Export!$A$2:$A$82,ReqSite_Export!$K$2:$K$82)) -> 6 | X10: =IF(AND(I10="Filled",N10="Approved"),J10-_xlfn.XLOOKUP(M10,ReqSite_Export!$A$2:$A$82,ReqSite_Export!$K$2:$K$82),"") -> 62 | Y10: =TRIM(D10) -> Sales
A11: 4110 | B11: RR-26-0011 | C11: Product Marketing Manager | D11: Mktg & Comms | E11: Olivia Chen | F11: Dana Whitaker | G11: Boston | H11: 46076 | I11: Filled | J11: 46148 | K11: LinkedIn | L11: 53 | M11: =TRIM(SUBSTITUTE(B11,CHAR(160),"")) -> RR-26-0011 | N11: =IF(M11="","Not found",_xlfn.XLOOKUP(M11,ReqSite_Export!$A$2:$A$82,ReqSite_Export!$J$2:$J$82,"Not found")) -> Approved | O11: =IF(N11="Not found","No request on file",IF(N11<>"Approved","Opened before approval","OK")) -> OK | P11: =IF(N11="Not found","",_xlfn.XLOOKUP(M11,ReqSite_Export!$A$2:$A$82,ReqSite_Export!$E$2:$E$82,"")) -> Product Marketing Manager | Q11: =IF(P11="","",TRIM(C11)=TRIM(P11)) -> TRUE | R11: =IF(N11="Not found","",_xlfn.XLOOKUP(M11,ReqSite_Export!$A$2:$A$82,ReqSite_Export!$C$2:$C$82,"")) -> Olivia Chen | S11: =IF(R11="","",TRIM(E11)=TRIM(R11)) -> TRUE | T11: =IF(N11="Not found","",_xlfn.XLOOKUP(M11,ReqSite_Export!$A$2:$A$82,ReqSite_Export!$D$2:$D$82,"")) -> Marketing | U11: =IF(T11="","",TRIM(D11)=_xlfn.XLOOKUP(T11,Dept_Map!$A$2:$A$11,Dept_Map!$B$2:$B$11,"")) -> TRUE | V11: =IF(ISTEXT(H11),DATEVALUE(H11),H11) -> 46076 | W11: =IF(N11<>"Approved","",V11-_xlfn.XLOOKUP(M11,ReqSite_Export!$A$2:$A$82,ReqSite_Export!$K$2:$K$82)) -> 3 | X11: =IF(AND(I11="Filled",N11="Approved"),J11-_xlfn.XLOOKUP(M11,ReqSite_Export!$A$2:$A$82,ReqSite_Export!$K$2:$K$82),"") -> 75 | Y11: =TRIM(D11) -> Mktg & Comms
A12: 4111 | B12: N/A | C12: Event Coordinator | D12: Events | E12: Grace Holloway | F12: Dana Whitaker | G12: Boston | H12: 46083 | I12: Filled | J12: 46132 | K12: Employee Referral | L12: 64 | M12: =TRIM(SUBSTITUTE(B12,CHAR(160),"")) -> N/A | N12: =IF(M12="","Not found",_xlfn.XLOOKUP(M12,ReqSite_Export!$A$2:$A$82,ReqSite_Export!$J$2:$J$82,"Not found")) -> Not found | O12: =IF(N12="Not found","No request on file",IF(N12<>"Approved","Opened before approval","OK")) -> No request on file | P12: =IF(N12="Not found","",_xlfn.XLOOKUP(M12,ReqSite_Export!$A$2:$A$82,ReqSite_Export!$E$2:$E$82,"")) | Q12: =IF(P12="","",TRIM(C12)=TRIM(P12)) | R12: =IF(N12="Not found","",_xlfn.XLOOKUP(M12,ReqSite_Export!$A$2:$A$82,ReqSite_Export!$C$2:$C$82,"")) | S12: =IF(R12="","",TRIM(E12)=TRIM(R12)) | T12: =IF(N12="Not found","",_xlfn.XLOOKUP(M12,ReqSite_Export!$A$2:$A$82,ReqSite_Export!$D$2:$D$82,"")) | U12: =IF(T12="","",TRIM(D12)=_xlfn.XLOOKUP(T12,Dept_Map!$A$2:$A$11,Dept_Map!$B$2:$B$11,"")) | V12: =IF(ISTEXT(H12),DATEVALUE(H12),H12) -> 46083 | W12: =IF(N12<>"Approved","",V12-_xlfn.XLOOKUP(M12,ReqSite_Export!$A$2:$A$82,ReqSite_Export!$K$2:$K$82)) | X12: =IF(AND(I12="Filled",N12="Approved"),J12-_xlfn.XLOOKUP(M12,ReqSite_Export!$A$2:$A$82,ReqSite_Export!$K$2:$K$82),"") | Y12: =TRIM(D12) -> Events
A13: 4112 | B13: RR-26-0012 | C13: Senior Product Manager | D13: Product Mgmt | E13: Daniel Osei | F13: Imani Brooks | G13: London | H13: 46090 | I13: Cancelled | L13: 74 | M13: =TRIM(SUBSTITUTE(B13,CHAR(160),"")) -> RR-26-0012 | N13: =IF(M13="","Not found",_xlfn.XLOOKUP(M13,ReqSite_Export!$A$2:$A$82,ReqSite_Export!$J$2:$J$82,"Not found")) -> Approved | O13: =IF(N13="Not found","No request on file",IF(N13<>"Approved","Opened before approval","OK")) -> OK | P13: =IF(N13="Not found","",_xlfn.XLOOKUP(M13,ReqSite_Export!$A$2:$A$82,ReqSite_Export!$E$2:$E$82,"")) -> Senior Product Manager | Q13: =IF(P13="","",TRIM(C13)=TRIM(P13)) -> TRUE | R13: =IF(N13="Not found","",_xlfn.XLOOKUP(M13,ReqSite_Export!$A$2:$A$82,ReqSite_Export!$C$2:$C$82,"")) -> Daniel Osei | S13: =IF(R13="","",TRIM(E13)=TRIM(R13)) -> TRUE | T13: =IF(N13="Not found","",_xlfn.XLOOKUP(M13,ReqSite_Export!$A$2:$A$82,ReqSite_Export!$D$2:$D$82,"")) -> Product | U13: =IF(T13="","",TRIM(D13)=_xlfn.XLOOKUP(T13,Dept_Map!$A$2:$A$11,Dept_Map!$B$2:$B$11,"")) -> TRUE | V13: =IF(ISTEXT(H13),DATEVALUE(H13),H13) -> 46090 | W13: =IF(N13<>"Approved","",V13-_xlfn.XLOOKUP(M13,ReqSite_Export!$A$2:$A$82,ReqSite_Export!$K$2:$K$82)) -> 6 | X13: =IF(AND(I13="Filled",N13="Approved"),J13-_xlfn.XLOOKUP(M13,ReqSite_Export!$A$2:$A$82,ReqSite_Export!$K$2:$K$82),"") | Y13: =TRIM(D13) -> Product Mgmt
A14: 4113 | B14: RR-26-0010 | C14: Event Marketing Manager | D14: Events | E14: Grace Holloway | F14: Dana Whitaker | G14: London | H14: 46092 | I14: Filled | J14: 46141 | K14: LinkedIn | L14: 20 | M14: =TRIM(SUBSTITUTE(B14,CHAR(160),"")) -> RR-26-0010 | N14: =IF(M14="","Not found",_xlfn.XLOOKUP(M14,ReqSite_Export!$A$2:$A$82,ReqSite_Export!$J$2:$J$82,"Not found")) -> Approved | O14: =IF(N14="Not found","No request on file",IF(N14<>"Approved","Opened before approval","OK")) -> OK | P14: =IF(N14="Not found","",_xlfn.XLOOKUP(M14,ReqSite_Export!$A$2:$A$82,ReqSite_Export!$E$2:$E$82,"")) -> Event Marketing Manager | Q14: =IF(P14="","",TRIM(C14)=TRIM(P14)) -> TRUE | R14: =IF(N14="Not found","",_xlfn.XLOOKUP(M14,ReqSite_Export!$A$2:$A$82,ReqSite_Export!$C$2:$C$82,"")) -> Grace Holloway | S14: =IF(R14="","",TRIM(E14)=TRIM(R14)) -> TRUE | T14: =IF(N14="Not found","",_xlfn.XLOOKUP(M14,ReqSite_Export!$A$2:$A$82,ReqSite_Export!$D$2:$D$82,"")) -> Events | U14: =IF(T14="","",TRIM(D14)=_xlfn.XLOOKUP(T14,Dept_Map!$A$2:$A$11,Dept_Map!$B$2:$B$11,"")) -> TRUE | V14: =IF(ISTEXT(H14),DATEVALUE(H14),H14) -> 46092 | W14: =IF(N14<>"Approved","",V14-_xlfn.XLOOKUP(M14,ReqSite_Export!$A$2:$A$82,ReqSite_Export!$K$2:$K$82)) -> 16 | X14: =IF(AND(I14="Filled",N14="Approved"),J14-_xlfn.XLOOKUP(M14,ReqSite_Export!$A$2:$A$82,ReqSite_Export!$K$2:$K$82),"") -> 65 | Y14: =TRIM(D14) -> Events
A15: 4114 | B15: RR-26-0015 | C15: Engagement Manager | D15: Consulting Services | E15: Sofia Marino | F15: Chris Palmer | G15: Toronto | H15: 46097 | I15: Filled | J15: 46157 | K15: LinkedIn | L15: 68 | M15: =TRIM(SUBSTITUTE(B15,CHAR(160),"")) -> RR-26-0015 | N15: =IF(M15="","Not found",_xlfn.XLOOKUP(M15,ReqSite_Export!$A$2:$A$82,ReqSite_Export!$J$2:$J$82,"Not found")) -> Approved | O15: =IF(N15="Not found","No request on file",IF(N15<>"Approved","Opened before approval","OK")) -> OK | P15: =IF(N15="Not found","",_xlfn.XLOOKUP(M15,ReqSite_Export!$A$2:$A$82,ReqSite_Export!$E$2:$E$82,"")) -> Engagement Manager | Q15: =IF(P15="","",TRIM(C15)=TRIM(P15)) -> TRUE | R15: =IF(N15="Not found","",_xlfn.XLOOKUP(M15,ReqSite_Export!$A$2:$A$82,ReqSite_Export!$C$2:$C$82,"")) -> Sofia Marino | S15: =IF(R15="","",TRIM(E15)=TRIM(R15)) -> TRUE | T15: =IF(N15="Not found","",_xlfn.XLOOKUP(M15,ReqSite_Export!$A$2:$A$82,ReqSite_Export!$D$2:$D$82,"")) -> Consulting | U15: =IF(T15="","",TRIM(D15)=_xlfn.XLOOKUP(T15,Dept_Map!$A$2:$A$11,Dept_Map!$B$2:$B$11,"")) -> TRUE | V15: =IF(ISTEXT(H15),DATEVALUE(H15),H15) -> 46097 | W15: =IF(N15<>"Approved","",V15-_xlfn.XLOOKUP(M15,ReqSite_Export!$A$2:$A$82,ReqSite_Export!$K$2:$K$82)) -> 3 | X15: =IF(AND(I15="Filled",N15="Approved"),J15-_xlfn.XLOOKUP(M15,ReqSite_Export!$A$2:$A$82,ReqSite_Export!$K$2:$K$82),"") -> 63 | Y15: =TRIM(D15) -> Consulting Services
A16: 4115 | B16: RR-26-0014 | C16: HRIS Analyst | D16: HR | E16: Julia Novak | F16: Owen Fitzgerald | G16: Boston | H16: 46100 | I16: Filled | J16: 46143 | K16: Careers Site | L16: 21 | M16: =TRIM(SUBSTITUTE(B16,CHAR(160),"")) -> RR-26-0014 | N16: =IF(M16="","Not found",_xlfn.XLOOKUP(M16,ReqSite_Export!$A$2:$A$82,ReqSite_Export!$J$2:$J$82,"Not found")) -> Approved | O16: =IF(N16="Not found","No request on file",IF(N16<>"Approved","Opened before approval","OK")) -> OK | P16: =IF(N16="Not found","",_xlfn.XLOOKUP(M16,ReqSite_Export!$A$2:$A$82,ReqSite_Export!$E$2:$E$82,"")) -> HRIS Analyst | Q16: =IF(P16="","",TRIM(C16)=TRIM(P16)) -> TRUE | R16: =IF(N16="Not found","",_xlfn.XLOOKUP(M16,ReqSite_Export!$A$2:$A$82,ReqSite_Export!$C$2:$C$82,"")) -> Julia Novak | S16: =IF(R16="","",TRIM(E16)=TRIM(R16)) -> TRUE | T16: =IF(N16="Not found","",_xlfn.XLOOKUP(M16,ReqSite_Export!$A$2:$A$82,ReqSite_Export!$D$2:$D$82,"")) -> Human Resources | U16: =IF(T16="","",TRIM(D16)=_xlfn.XLOOKUP(T16,Dept_Map!$A$2:$A$11,Dept_Map!$B$2:$B$11,"")) -> TRUE | V16: =IF(ISTEXT(H16),DATEVALUE(H16),H16) -> 46100 | W16: =IF(N16<>"Approved","",V16-_xlfn.XLOOKUP(M16,ReqSite_Export!$A$2:$A$82,ReqSite_Export!$K$2:$K$82)) -> 3 | X16: =IF(AND(I16="Filled",N16="Approved"),J16-_xlfn.XLOOKUP(M16,ReqSite_Export!$A$2:$A$82,ReqSite_Export!$K$2:$K$82),"") -> 46 | Y16: =TRIM(D16) -> HR
A17: 4116 | B17: RR-26-0016 | C17: Data Engineer | D17: Data and Analytics | E17: Amy Sorensen | F17: Imani Brooks | G17: Boston | H17: 46101 | I17: Filled | J17: 46126 | K17: Agency | L17: 98 | M17: =TRIM(SUBSTITUTE(B17,CHAR(160),"")) -> RR-26-0016 | N17: =IF(M17="","Not found",_xlfn.XLOOKUP(M17,ReqSite_Export!$A$2:$A$82,ReqSite_Export!$J$2:$J$82,"Not found")) -> Approved | O17: =IF(N17="Not found","No request on file",IF(N17<>"Approved","Opened before approval","OK")) -> OK | P17: =IF(N17="Not found","",_xlfn.XLOOKUP(M17,ReqSite_Export!$A$2:$A$82,ReqSite_Export!$E$2:$E$82,"")) -> Data Engineer | Q17: =IF(P17="","",TRIM(C17)=TRIM(P17)) -> TRUE | R17: =IF(N17="Not found","",_xlfn.XLOOKUP(M17,ReqSite_Export!$A$2:$A$82,ReqSite_Export!$C$2:$C$82,"")) -> Amy Sorensen | S17: =IF(R17="","",TRIM(E17)=TRIM(R17)) -> TRUE | T17: =IF(N17="Not found","",_xlfn.XLOOKUP(M17,ReqSite_Export!$A$2:$A$82,ReqSite_Export!$D$2:$D$82,"")) -> Data & Analytics | U17: =IF(T17="","",TRIM(D17)=_xlfn.XLOOKUP(T17,Dept_Map!$A$2:$A$11,Dept_Map!$B$2:$B$11,"")) -> TRUE | V17: =IF(ISTEXT(H17),DATEVALUE(H17),H17) -> 46101 | W17: =IF(N17<>"Approved","",V17-_xlfn.XLOOKUP(M17,ReqSite_Export!$A$2:$A$82,ReqSite_Export!$K$2:$K$82)) -> 2 | X17: =IF(AND(I17="Filled",N17="Approved"),J17-_xlfn.XLOOKUP(M17,ReqSite_Export!$A$2:$A$82,ReqSite_Export!$K$2:$K$82),"") -> 27 | Y17: =TRIM(D17) -> Data and Analytics
A18: 4117 | B18: RR-26-0020 | C18: Event Marketing Manager | D18: Events | E18: Grace Holloway | F18: Dana Whitaker | G18: London | H18: 46121 | I18: Filled | J18: 46167 | K18: Employee Referral | L18: 24 | M18: =TRIM(SUBSTITUTE(B18,CHAR(160),"")) -> RR-26-0020 | N18: =IF(M18="","Not found",_xlfn.XLOOKUP(M18,ReqSite_Export!$A$2:$A$82,ReqSite_Export!$J$2:$J$82,"Not found")) -> Approved | O18: =IF(N18="Not found","No request on file",IF(N18<>"Approved","Opened before approval","OK")) -> OK | P18: =IF(N18="Not found","",_xlfn.XLOOKUP(M18,ReqSite_Export!$A$2:$A$82,ReqSite_Export!$E$2:$E$82,"")) -> Event Marketing Manager | Q18: =IF(P18="","",TRIM(C18)=TRIM(P18)) -> TRUE | R18: =IF(N18="Not found","",_xlfn.XLOOKUP(M18,ReqSite_Export!$A$2:$A$82,ReqSite_Export!$C$2:$C$82,"")) -> Grace Holloway | S18: =IF(R18="","",TRIM(E18)=TRIM(R18)) -> TRUE | T18: =IF(N18="Not found","",_xlfn.XLOOKUP(M18,ReqSite_Export!$A$2:$A$82,ReqSite_Export!$D$2:$D$82,"")) -> Events | U18: =IF(T18="","",TRIM(D18)=_xlfn.XLOOKUP(T18,Dept_Map!$A$2:$A$11,Dept_Map!$B$2:$B$11,"")) -> TRUE | V18: =IF(ISTEXT(H18),DATEVALUE(H18),H18) -> 46121 | W18: =IF(N18<>"Approved","",V18-_xlfn.XLOOKUP(M18,ReqSite_Export!$A$2:$A$82,ReqSite_Export!$K$2:$K$82)) -> 3 | X18: =IF(AND(I18="Filled",N18="Approved"),J18-_xlfn.XLOOKUP(M18,ReqSite_Export!$A$2:$A$82,ReqSite_Export!$K$2:$K$82),"") -> 49 | Y18: =TRIM(D18) -> Events
A19: 4118 | B19: RR-26-0017 | C19: Senior Accountant | D19: Finance | E19: Lisa Tran | F19: Owen Fitzgerald | G19: Boston | H19: 46125 | I19: Filled | J19: 46202 | K19: LinkedIn | L19: 44 | M19: =TRIM(SUBSTITUTE(B19,CHAR(160),"")) -> RR-26-0017 | N19: =IF(M19="","Not found",_xlfn.XLOOKUP(M19,ReqSite_Export!$A$2:$A$82,ReqSite_Export!$J$2:$J$82,"Not found")) -> Approved | O19: =IF(N19="Not found","No request on file",IF(N19<>"Approved","Opened before approval","OK")) -> OK | P19: =IF(N19="Not found","",_xlfn.XLOOKUP(M19,ReqSite_Export!$A$2:$A$82,ReqSite_Export!$E$2:$E$82,"")) -> Senior Accountant | Q19: =IF(P19="","",TRIM(C19)=TRIM(P19)) -> TRUE | R19: =IF(N19="Not found","",_xlfn.XLOOKUP(M19,ReqSite_Export!$A$2:$A$82,ReqSite_Export!$C$2:$C$82,"")) -> Lisa Tran | S19: =IF(R19="","",TRIM(E19)=TRIM(R19)) -> TRUE | T19: =IF(N19="Not found","",_xlfn.XLOOKUP(M19,ReqSite_Export!$A$2:$A$82,ReqSite_Export!$D$2:$D$82,"")) -> Finance | U19: =IF(T19="","",TRIM(D19)=_xlfn.XLOOKUP(T19,Dept_Map!$A$2:$A$11,Dept_Map!$B$2:$B$11,"")) -> TRUE | V19: =IF(ISTEXT(H19),DATEVALUE(H19),H19) -> 46125 | W19: =IF(N19<>"Approved","",V19-_xlfn.XLOOKUP(M19,ReqSite_Export!$A$2:$A$82,ReqSite_Export!$K$2:$K$82)) -> 4 | X19: =IF(AND(I19="Filled",N19="Approved"),J19-_xlfn.XLOOKUP(M19,ReqSite_Export!$A$2:$A$82,ReqSite_Export!$K$2:$K$82),"") -> 81 | Y19: =TRIM(D19) -> Finance
A20: 4119 | B20: RR-26-0022 | C20: Content Marketing Manager | D20: Events | E20: Olivia Chen | F20: Dana Whitaker | G20: Boston | H20: 46139 | I20: Filled | J20: 46190 | K20: Employee Referral | L20: 77 | M20: =TRIM(SUBSTITUTE(B20,CHAR(160),"")) -> RR-26-0022 | N20: =IF(M20="","Not found",_xlfn.XLOOKUP(M20,ReqSite_Export!$A$2:$A$82,ReqSite_Export!$J$2:$J$82,"Not found")) -> Approved | O20: =IF(N20="Not found","No request on file",IF(N20<>"Approved","Opened before approval","OK")) -> OK | P20: =IF(N20="Not found","",_xlfn.XLOOKUP(M20,ReqSite_Export!$A$2:$A$82,ReqSite_Export!$E$2:$E$82,"")) -> Content Marketing Manager | Q20: =IF(P20="","",TRIM(C20)=TRIM(P20)) -> TRUE | R20: =IF(N20="Not found","",_xlfn.XLOOKUP(M20,ReqSite_Export!$A$2:$A$82,ReqSite_Export!$C$2:$C$82,"")) -> Olivia Chen | S20: =IF(R20="","",TRIM(E20)=TRIM(R20)) -> TRUE | T20: =IF(N20="Not found","",_xlfn.XLOOKUP(M20,ReqSite_Export!$A$2:$A$82,ReqSite_Export!$D$2:$D$82,"")) -> Marketing | U20: =IF(T20="","",TRIM(D20)=_xlfn.XLOOKUP(T20,Dept_Map!$A$2:$A$11,Dept_Map!$B$2:$B$11,"")) -> FALSE | V20: =IF(ISTEXT(H20),DATEVALUE(H20),H20) -> 46139 | W20: =IF(N20<>"Approved","",V20-_xlfn.XLOOKUP(M20,ReqSite_Export!$A$2:$A$82,ReqSite_Export!$K$2:$K$82)) -> 13 | X20: =IF(AND(I20="Filled",N20="Approved"),J20-_xlfn.XLOOKUP(M20,ReqSite_Export!$A$2:$A$82,ReqSite_Export!$K$2:$K$82),"") -> 64 | Y20: =TRIM(D20) -> Events
